<?xml version="1.0"?>
<robot name="my_robot">
    <link name="base_link">
        <visual>
            <geometry>
                <box size=".05 .05 .3"/>
            </geometry>
            <origin xyz="0 0 0.15" rpy="0 0 0" />
        </visual>
    </link>
    <link name="linkA">
        <visual>
            <geometry>
                <box size=".05 .05 .3"/>
            </geometry>
            <origin xyz="0 0 0.15" rpy="0 0 0" />
        </visual>
    </link>
    <link name="linkB">
        <visual>
            <geometry>
                <box size=".05 .05 .3"/>
            </geometry>
            <origin xyz="0 0 0.15" rpy="0 0 0" />
        </visual>
    </link>

    <joint name="A" type="continuous">
        <parent link="base_link"/>
        <child link="linkA"/>
        <origin xyz="0 0 .3" rpy="0 0 0" />
        <axis xyz="1 0 0" />
    </joint>

    <joint name="B" type="continuous">
        <parent link="linkA"/>
        <child link="linkB"/>
        <origin xyz="0 0 .3" rpy="0 0 0" />
        <axis xyz="0 1 0" />
    </joint>
</robot>
